<?xml version="1.0"?>
<robot name="Body">
    <link name="robot_base">
        <inertial>
            <origin rpy="-0.000000 -1.570796 0.000000" xyz="3.085511 -5.252829 0.187957" />
            <inertia ixy="-9.2003324889779e-06" ixx="0.042153030412219" izz="0.0070709197939428" iyz="-0.00022444305582477" iyy="0.035836070888816" ixz="1.6089393589153e-05" />
            <mass value="2.4" />
        </inertial>
        <collision name="Body">
            <origin rpy="0.000000 -1.570796 0.000000" xyz="3.085000 -5.253000 0.193995" />
            <geometry>
                <mesh filename="file://C:/Users/hp/Desktop/poly2/poly2_robot_base_coll_1.dae" />
            </geometry>
        </collision>
        <collision name="Body">
            <origin rpy="0.000000 -1.570796 0.000000" xyz="3.085000 -5.253000 0.193995" />
            <geometry>
                <mesh filename="file://C:/Users/hp/Desktop/poly2/poly2_robot_base_coll_2.dae" />
            </geometry>
        </collision>
        <collision name="Body">
            <origin rpy="0.000000 -1.570796 0.000000" xyz="3.085000 -5.253000 0.193995" />
            <geometry>
                <mesh filename="file://C:/Users/hp/Desktop/poly2/poly2_robot_base_coll_3.dae" />
            </geometry>
        </collision>
        <collision name="Body">
            <origin rpy="0.000000 -1.570796 0.000000" xyz="3.085000 -5.253000 0.193995" />
            <geometry>
                <mesh filename="file://C:/Users/hp/Desktop/poly2/poly2_robot_base_coll_4.dae" />
            </geometry>
        </collision>
        <collision name="Body">
            <origin rpy="0.000000 -1.570796 0.000000" xyz="3.085000 -5.253000 0.193995" />
            <geometry>
                <mesh filename="file://C:/Users/hp/Desktop/poly2/poly2_robot_base_coll_5.dae" />
            </geometry>
        </collision>
        <collision name="Body">
            <origin rpy="0.000000 -1.570796 0.000000" xyz="3.085000 -5.253000 0.193995" />
            <geometry>
                <mesh filename="file://C:/Users/hp/Desktop/poly2/poly2_robot_base_coll_6.dae" />
            </geometry>
        </collision>
        <collision name="Body">
            <origin rpy="0.000000 -1.570796 0.000000" xyz="3.085000 -5.253000 0.193995" />
            <geometry>
                <mesh filename="file://C:/Users/hp/Desktop/poly2/poly2_robot_base_coll_7.dae" />
            </geometry>
        </collision>
        <collision name="Body">
            <origin rpy="0.000000 -1.570796 0.000000" xyz="3.085000 -5.253000 0.193995" />
            <geometry>
                <mesh filename="file://C:/Users/hp/Desktop/poly2/poly2_robot_base_coll_8.dae" />
            </geometry>
        </collision>
        <collision name="Body">
            <origin rpy="0.000000 -1.570796 0.000000" xyz="3.085000 -5.253000 0.193995" />
            <geometry>
                <mesh filename="file://C:/Users/hp/Desktop/poly2/poly2_robot_base_coll_9.dae" />
            </geometry>
        </collision>
        <collision name="Body">
            <origin rpy="0.000000 -1.570796 0.000000" xyz="3.085000 -5.253000 0.193995" />
            <geometry>
                <mesh filename="file://C:/Users/hp/Desktop/poly2/poly2_robot_base_coll_10.dae" />
            </geometry>
        </collision>
        <collision name="Body">
            <origin rpy="0.000000 -1.570796 0.000000" xyz="3.085000 -5.253000 0.193995" />
            <geometry>
                <mesh filename="file://C:/Users/hp/Desktop/poly2/poly2_robot_base_coll_11.dae" />
            </geometry>
        </collision>
        <collision name="Body">
            <origin rpy="0.000000 -1.570796 0.000000" xyz="3.085000 -5.253000 0.193995" />
            <geometry>
                <mesh filename="file://C:/Users/hp/Desktop/poly2/poly2_robot_base_coll_12.dae" />
            </geometry>
        </collision>
        <collision name="Body">
            <origin rpy="0.000000 -1.570796 0.000000" xyz="3.085000 -5.253000 0.193995" />
            <geometry>
                <mesh filename="file://C:/Users/hp/Desktop/poly2/poly2_robot_base_coll_13.dae" />
            </geometry>
        </collision>
        <collision name="Body">
            <origin rpy="0.000000 -1.570796 0.000000" xyz="3.085000 -5.253000 0.193995" />
            <geometry>
                <mesh filename="file://C:/Users/hp/Desktop/poly2/poly2_robot_base_coll_14.dae" />
            </geometry>
        </collision>
        <collision name="Body">
            <origin rpy="0.000000 -1.570796 0.000000" xyz="3.085000 -5.253000 0.193995" />
            <geometry>
                <mesh filename="file://C:/Users/hp/Desktop/poly2/poly2_robot_base_coll_15.dae" />
            </geometry>
        </collision>
        <collision name="Body">
            <origin rpy="0.000000 -1.570796 0.000000" xyz="3.085000 -5.253000 0.193995" />
            <geometry>
                <mesh filename="file://C:/Users/hp/Desktop/poly2/poly2_robot_base_coll_16.dae" />
            </geometry>
        </collision>
        <collision name="Body">
            <origin rpy="0.000000 -1.570796 0.000000" xyz="3.085000 -5.253000 0.193995" />
            <geometry>
                <mesh filename="file://C:/Users/hp/Desktop/poly2/poly2_robot_base_coll_17.dae" />
            </geometry>
        </collision>
        <collision name="Body">
            <origin rpy="0.000000 -1.570796 0.000000" xyz="3.085000 -5.253000 0.193995" />
            <geometry>
                <mesh filename="file://C:/Users/hp/Desktop/poly2/poly2_robot_base_coll_18.dae" />
            </geometry>
        </collision>
        <collision name="Body">
            <origin rpy="0.000000 -1.570796 0.000000" xyz="3.085000 -5.253000 0.193995" />
            <geometry>
                <mesh filename="file://C:/Users/hp/Desktop/poly2/poly2_robot_base_coll_19.dae" />
            </geometry>
        </collision>
        <collision name="Body">
            <origin rpy="0.000000 -1.570796 0.000000" xyz="3.085000 -5.253000 0.193995" />
            <geometry>
                <mesh filename="file://C:/Users/hp/Desktop/poly2/poly2_robot_base_coll_20.dae" />
            </geometry>
        </collision>
        <collision name="Body">
            <origin rpy="0.000000 -1.570796 0.000000" xyz="3.085000 -5.253000 0.193995" />
            <geometry>
                <mesh filename="file://C:/Users/hp/Desktop/poly2/poly2_robot_base_coll_21.dae" />
            </geometry>
        </collision>
        <collision name="Body">
            <origin rpy="0.000000 -1.570796 0.000000" xyz="3.085000 -5.253000 0.193995" />
            <geometry>
                <mesh filename="file://C:/Users/hp/Desktop/poly2/poly2_robot_base_coll_22.dae" />
            </geometry>
        </collision>
        <collision name="Body">
            <origin rpy="0.000000 -1.570796 0.000000" xyz="3.085000 -5.253000 0.193995" />
            <geometry>
                <mesh filename="file://C:/Users/hp/Desktop/poly2/poly2_robot_base_coll_23.dae" />
            </geometry>
        </collision>
        <collision name="Body">
            <origin rpy="0.000000 -1.570796 0.000000" xyz="3.085000 -5.253000 0.193995" />
            <geometry>
                <mesh filename="file://C:/Users/hp/Desktop/poly2/poly2_robot_base_coll_24.dae" />
            </geometry>
        </collision>
        <collision name="Body">
            <origin rpy="0.000000 -1.570796 0.000000" xyz="3.085000 -5.253000 0.193995" />
            <geometry>
                <mesh filename="file://C:/Users/hp/Desktop/poly2/poly2_robot_base_coll_25.dae" />
            </geometry>
        </collision>
        <collision name="Body">
            <origin rpy="0.000000 -1.570796 0.000000" xyz="3.085000 -5.253000 0.193995" />
            <geometry>
                <mesh filename="file://C:/Users/hp/Desktop/poly2/poly2_robot_base_coll_26.dae" />
            </geometry>
        </collision>
        <collision name="Body">
            <origin rpy="0.000000 -1.570796 0.000000" xyz="3.085000 -5.253000 0.193995" />
            <geometry>
                <mesh filename="file://C:/Users/hp/Desktop/poly2/poly2_robot_base_coll_27.dae" />
            </geometry>
        </collision>
        <collision name="Body">
            <origin rpy="0.000000 -1.570796 0.000000" xyz="3.085000 -5.253000 0.193995" />
            <geometry>
                <mesh filename="file://C:/Users/hp/Desktop/poly2/poly2_robot_base_coll_28.dae" />
            </geometry>
        </collision>
        <collision name="Body">
            <origin rpy="0.000000 -1.570796 0.000000" xyz="3.085000 -5.253000 0.193995" />
            <geometry>
                <mesh filename="file://C:/Users/hp/Desktop/poly2/poly2_robot_base_coll_29.dae" />
            </geometry>
        </collision>
        <collision name="Body">
            <origin rpy="0.000000 -1.570796 0.000000" xyz="3.085000 -5.253000 0.193995" />
            <geometry>
                <mesh filename="file://C:/Users/hp/Desktop/poly2/poly2_robot_base_coll_30.dae" />
            </geometry>
        </collision>
        <collision name="Body">
            <origin rpy="0.000000 -1.570796 0.000000" xyz="3.085000 -5.253000 0.193995" />
            <geometry>
                <mesh filename="file://C:/Users/hp/Desktop/poly2/poly2_robot_base_coll_31.dae" />
            </geometry>
        </collision>
        <collision name="Body">
            <origin rpy="0.000000 -1.570796 0.000000" xyz="3.085000 -5.253000 0.193995" />
            <geometry>
                <mesh filename="file://C:/Users/hp/Desktop/poly2/poly2_robot_base_coll_32.dae" />
            </geometry>
        </collision>
        <visual name="Body_visual">
            <origin rpy="0.000000 -1.570796 0.000000" xyz="3.085000 -5.253000 0.193995" />
            <geometry>
                <mesh filename="file://C:/Users/hp/Desktop/poly2/poly2_Bodyvisual_vis_1.dae" />
            </geometry>
            <material name="Bodyvisual_material">
                <color rgba="0.490000 0.680000 0.980000 1.0" />
            </material>
        </visual>
    </link>
    <joint name="Shoulder4" type="revolute">
        <axis xyz="0 0 1" />
        <limit upper="3.1415920706652" velocity="6.2831854820251" effort="2.5" lower="-3.14159341136" />
        <parent link="robot_base" />
        <child link="Case4" />
        <origin rpy="3.078568 1.588567 -0.083163" xyz="2.955599 -5.173379 0.196405" />
    </joint>
    <link name="Case4">
        <collision name="Case4">
            <origin rpy="-0.000000 3.141593 0.000001" xyz="0.000255 0.001198 -0.009000" />
            <geometry>
                <mesh filename="file://C:/Users/hp/Desktop/poly2/poly2_Case4_coll_1.dae" />
            </geometry>
        </collision>
        <collision name="Case4">
            <origin rpy="-0.000000 3.141593 0.000001" xyz="0.000255 0.001198 -0.009000" />
            <geometry>
                <mesh filename="file://C:/Users/hp/Desktop/poly2/poly2_Case4_coll_2.dae" />
            </geometry>
        </collision>
        <collision name="Case4">
            <origin rpy="-0.000000 3.141593 0.000001" xyz="0.000255 0.001198 -0.009000" />
            <geometry>
                <mesh filename="file://C:/Users/hp/Desktop/poly2/poly2_Case4_coll_3.dae" />
            </geometry>
        </collision>
        <collision name="Case4">
            <origin rpy="-0.000000 3.141593 0.000001" xyz="0.000255 0.001198 -0.009000" />
            <geometry>
                <mesh filename="file://C:/Users/hp/Desktop/poly2/poly2_Case4_coll_4.dae" />
            </geometry>
        </collision>
        <collision name="Case4">
            <origin rpy="-0.000000 3.141593 0.000001" xyz="0.000255 0.001198 -0.009000" />
            <geometry>
                <mesh filename="file://C:/Users/hp/Desktop/poly2/poly2_Case4_coll_5.dae" />
            </geometry>
        </collision>
        <collision name="Case4">
            <origin rpy="-0.000000 3.141593 0.000001" xyz="0.000255 0.001198 -0.009000" />
            <geometry>
                <mesh filename="file://C:/Users/hp/Desktop/poly2/poly2_Case4_coll_6.dae" />
            </geometry>
        </collision>
        <collision name="Case4">
            <origin rpy="-0.000000 3.141593 0.000001" xyz="0.000255 0.001198 -0.009000" />
            <geometry>
                <mesh filename="file://C:/Users/hp/Desktop/poly2/poly2_Case4_coll_7.dae" />
            </geometry>
        </collision>
        <collision name="Case4">
            <origin rpy="-0.000000 3.141593 0.000001" xyz="0.000255 0.001198 -0.009000" />
            <geometry>
                <mesh filename="file://C:/Users/hp/Desktop/poly2/poly2_Case4_coll_8.dae" />
            </geometry>
        </collision>
        <collision name="Case4">
            <origin rpy="-0.000000 3.141593 0.000001" xyz="0.000255 0.001198 -0.009000" />
            <geometry>
                <mesh filename="file://C:/Users/hp/Desktop/poly2/poly2_Case4_coll_9.dae" />
            </geometry>
        </collision>
        <collision name="Case4">
            <origin rpy="-0.000000 3.141593 0.000001" xyz="0.000255 0.001198 -0.009000" />
            <geometry>
                <mesh filename="file://C:/Users/hp/Desktop/poly2/poly2_Case4_coll_10.dae" />
            </geometry>
        </collision>
        <collision name="Case4">
            <origin rpy="-0.000000 3.141593 0.000001" xyz="0.000255 0.001198 -0.009000" />
            <geometry>
                <mesh filename="file://C:/Users/hp/Desktop/poly2/poly2_Case4_coll_11.dae" />
            </geometry>
        </collision>
        <collision name="Case4">
            <origin rpy="-0.000000 3.141593 0.000001" xyz="0.000255 0.001198 -0.009000" />
            <geometry>
                <mesh filename="file://C:/Users/hp/Desktop/poly2/poly2_Case4_coll_12.dae" />
            </geometry>
        </collision>
        <collision name="Case4">
            <origin rpy="-0.000000 3.141593 0.000001" xyz="0.000255 0.001198 -0.009000" />
            <geometry>
                <mesh filename="file://C:/Users/hp/Desktop/poly2/poly2_Case4_coll_13.dae" />
            </geometry>
        </collision>
        <collision name="Case4">
            <origin rpy="-0.000000 3.141593 0.000001" xyz="0.000255 0.001198 -0.009000" />
            <geometry>
                <mesh filename="file://C:/Users/hp/Desktop/poly2/poly2_Case4_coll_14.dae" />
            </geometry>
        </collision>
        <collision name="Case4">
            <origin rpy="-0.000000 3.141593 0.000001" xyz="0.000255 0.001198 -0.009000" />
            <geometry>
                <mesh filename="file://C:/Users/hp/Desktop/poly2/poly2_Case4_coll_15.dae" />
            </geometry>
        </collision>
        <visual name="CaseD">
            <origin rpy="-0.000000 3.141593 0.000001" xyz="0.000255 0.001198 -0.009000" />
            <geometry>
                <mesh filename="file://C:/Users/hp/Desktop/poly2/poly2_CaseD_vis_1.dae" />
            </geometry>
            <material name="CaseD_material">
                <color rgba="0.000000 0.000000 0.000000 1.0" />
            </material>
        </visual>
    </link>
    <joint name="Hip4" type="revolute">
        <axis xyz="0 0 1" />
        <limit upper="3.1509636286646" velocity="6.2831854820251" effort="2.5" lower="-3.1322218533605" />
        <parent link="Case4" />
        <child link="Femur4" />
        <origin rpy="1.570797 -1.570796 0.000000" xyz="-0.000000 0.005000 0.021000" />
    </joint>
    <link name="Femur4">
        <collision name="Femur4">
            <origin rpy="-1.513971 4.553148 -2.691665" xyz="0.026693 -0.048463 0.033297" />
            <geometry>
                <mesh filename="file://C:/Users/hp/Desktop/poly2/poly2_Femur4_coll_1.dae" />
            </geometry>
        </collision>
        <collision name="Femur4">
            <origin rpy="-1.513971 4.553148 -2.691665" xyz="0.026693 -0.048463 0.033297" />
            <geometry>
                <mesh filename="file://C:/Users/hp/Desktop/poly2/poly2_Femur4_coll_2.dae" />
            </geometry>
        </collision>
        <collision name="Femur4">
            <origin rpy="-1.513971 4.553148 -2.691665" xyz="0.026693 -0.048463 0.033297" />
            <geometry>
                <mesh filename="file://C:/Users/hp/Desktop/poly2/poly2_Femur4_coll_3.dae" />
            </geometry>
        </collision>
        <collision name="Femur4">
            <origin rpy="-1.513971 4.553148 -2.691665" xyz="0.026693 -0.048463 0.033297" />
            <geometry>
                <mesh filename="file://C:/Users/hp/Desktop/poly2/poly2_Femur4_coll_4.dae" />
            </geometry>
        </collision>
        <collision name="Femur4">
            <origin rpy="-1.513971 4.553148 -2.691665" xyz="0.026693 -0.048463 0.033297" />
            <geometry>
                <mesh filename="file://C:/Users/hp/Desktop/poly2/poly2_Femur4_coll_5.dae" />
            </geometry>
        </collision>
        <collision name="Femur4">
            <origin rpy="-1.513971 4.553148 -2.691665" xyz="0.026693 -0.048463 0.033297" />
            <geometry>
                <mesh filename="file://C:/Users/hp/Desktop/poly2/poly2_Femur4_coll_6.dae" />
            </geometry>
        </collision>
        <collision name="Femur4">
            <origin rpy="-1.513971 4.553148 -2.691665" xyz="0.026693 -0.048463 0.033297" />
            <geometry>
                <mesh filename="file://C:/Users/hp/Desktop/poly2/poly2_Femur4_coll_7.dae" />
            </geometry>
        </collision>
        <collision name="Femur4">
            <origin rpy="-1.513971 4.553148 -2.691665" xyz="0.026693 -0.048463 0.033297" />
            <geometry>
                <mesh filename="file://C:/Users/hp/Desktop/poly2/poly2_Femur4_coll_8.dae" />
            </geometry>
        </collision>
        <collision name="Femur4">
            <origin rpy="-1.513971 4.553148 -2.691665" xyz="0.026693 -0.048463 0.033297" />
            <geometry>
                <mesh filename="file://C:/Users/hp/Desktop/poly2/poly2_Femur4_coll_9.dae" />
            </geometry>
        </collision>
        <collision name="Femur4">
            <origin rpy="-1.513971 4.553148 -2.691665" xyz="0.026693 -0.048463 0.033297" />
            <geometry>
                <mesh filename="file://C:/Users/hp/Desktop/poly2/poly2_Femur4_coll_10.dae" />
            </geometry>
        </collision>
        <collision name="Femur4">
            <origin rpy="-1.513971 4.553148 -2.691665" xyz="0.026693 -0.048463 0.033297" />
            <geometry>
                <mesh filename="file://C:/Users/hp/Desktop/poly2/poly2_Femur4_coll_11.dae" />
            </geometry>
        </collision>
        <collision name="Femur4">
            <origin rpy="-1.513971 4.553148 -2.691665" xyz="0.026693 -0.048463 0.033297" />
            <geometry>
                <mesh filename="file://C:/Users/hp/Desktop/poly2/poly2_Femur4_coll_12.dae" />
            </geometry>
        </collision>
        <collision name="Femur4">
            <origin rpy="-1.513971 4.553148 -2.691665" xyz="0.026693 -0.048463 0.033297" />
            <geometry>
                <mesh filename="file://C:/Users/hp/Desktop/poly2/poly2_Femur4_coll_13.dae" />
            </geometry>
        </collision>
        <collision name="Femur4">
            <origin rpy="-1.513971 4.553148 -2.691665" xyz="0.026693 -0.048463 0.033297" />
            <geometry>
                <mesh filename="file://C:/Users/hp/Desktop/poly2/poly2_Femur4_coll_14.dae" />
            </geometry>
        </collision>
        <collision name="Femur4">
            <origin rpy="-1.513971 4.553148 -2.691665" xyz="0.026693 -0.048463 0.033297" />
            <geometry>
                <mesh filename="file://C:/Users/hp/Desktop/poly2/poly2_Femur4_coll_15.dae" />
            </geometry>
        </collision>
        <collision name="Femur4">
            <origin rpy="-1.513971 4.553148 -2.691665" xyz="0.026693 -0.048463 0.033297" />
            <geometry>
                <mesh filename="file://C:/Users/hp/Desktop/poly2/poly2_Femur4_coll_16.dae" />
            </geometry>
        </collision>
        <collision name="Femur4">
            <origin rpy="-1.513971 4.553148 -2.691665" xyz="0.026693 -0.048463 0.033297" />
            <geometry>
                <mesh filename="file://C:/Users/hp/Desktop/poly2/poly2_Femur4_coll_17.dae" />
            </geometry>
        </collision>
        <collision name="Femur4">
            <origin rpy="-1.513971 4.553148 -2.691665" xyz="0.026693 -0.048463 0.033297" />
            <geometry>
                <mesh filename="file://C:/Users/hp/Desktop/poly2/poly2_Femur4_coll_18.dae" />
            </geometry>
        </collision>
        <visual name="FemurD">
            <origin rpy="-1.513971 4.553148 -2.691665" xyz="0.026693 -0.048463 0.033297" />
            <geometry>
                <mesh filename="file://C:/Users/hp/Desktop/poly2/poly2_FemurD_vis_1.dae" />
            </geometry>
            <material name="FemurD_material">
                <color rgba="0.000000 0.000000 0.000000 1.0" />
            </material>
        </visual>
    </link>
    <joint name="Knee4" type="revolute">
        <axis xyz="0 0 1" />
        <limit upper="3.1194358468056" velocity="6.2831854820251" effort="2.5" lower="-3.1637496352196" />
        <parent link="Femur4" />
        <child link="Tibia4" />
        <origin rpy="3.141593 3.141593 3.132222" xyz="0.077166 -0.104939 0.032297" />
    </joint>
    <link name="Tibia4">
        <collision name="Tibia4">
            <origin rpy="1.472774 2.285659 2.017877" xyz="-0.033693 -0.024713 -0.003985" />
            <geometry>
                <mesh filename="file://C:/Users/hp/Desktop/poly2/poly2_Tibia4_coll_1.dae" />
            </geometry>
        </collision>
        <collision name="Tibia4">
            <origin rpy="1.472774 2.285659 2.017877" xyz="-0.033693 -0.024713 -0.003985" />
            <geometry>
                <mesh filename="file://C:/Users/hp/Desktop/poly2/poly2_Tibia4_coll_2.dae" />
            </geometry>
        </collision>
        <collision name="Tibia4">
            <origin rpy="1.472774 2.285659 2.017877" xyz="-0.033693 -0.024713 -0.003985" />
            <geometry>
                <mesh filename="file://C:/Users/hp/Desktop/poly2/poly2_Tibia4_coll_3.dae" />
            </geometry>
        </collision>
        <collision name="Tibia4">
            <origin rpy="1.472774 2.285659 2.017877" xyz="-0.033693 -0.024713 -0.003985" />
            <geometry>
                <mesh filename="file://C:/Users/hp/Desktop/poly2/poly2_Tibia4_coll_4.dae" />
            </geometry>
        </collision>
        <collision name="Tibia4">
            <origin rpy="1.472774 2.285659 2.017877" xyz="-0.033693 -0.024713 -0.003985" />
            <geometry>
                <mesh filename="file://C:/Users/hp/Desktop/poly2/poly2_Tibia4_coll_5.dae" />
            </geometry>
        </collision>
        <collision name="Tibia4">
            <origin rpy="1.472774 2.285659 2.017877" xyz="-0.033693 -0.024713 -0.003985" />
            <geometry>
                <mesh filename="file://C:/Users/hp/Desktop/poly2/poly2_Tibia4_coll_6.dae" />
            </geometry>
        </collision>
        <collision name="Tibia4">
            <origin rpy="1.472774 2.285659 2.017877" xyz="-0.033693 -0.024713 -0.003985" />
            <geometry>
                <mesh filename="file://C:/Users/hp/Desktop/poly2/poly2_Tibia4_coll_7.dae" />
            </geometry>
        </collision>
        <collision name="Tibia4">
            <origin rpy="1.472774 2.285659 2.017877" xyz="-0.033693 -0.024713 -0.003985" />
            <geometry>
                <mesh filename="file://C:/Users/hp/Desktop/poly2/poly2_Tibia4_coll_8.dae" />
            </geometry>
        </collision>
        <collision name="Tibia4">
            <origin rpy="1.472774 2.285659 2.017877" xyz="-0.033693 -0.024713 -0.003985" />
            <geometry>
                <mesh filename="file://C:/Users/hp/Desktop/poly2/poly2_Tibia4_coll_9.dae" />
            </geometry>
        </collision>
        <collision name="Tibia4">
            <origin rpy="1.472774 2.285659 2.017877" xyz="-0.033693 -0.024713 -0.003985" />
            <geometry>
                <mesh filename="file://C:/Users/hp/Desktop/poly2/poly2_Tibia4_coll_10.dae" />
            </geometry>
        </collision>
        <collision name="Tibia4">
            <origin rpy="1.472774 2.285659 2.017877" xyz="-0.033693 -0.024713 -0.003985" />
            <geometry>
                <mesh filename="file://C:/Users/hp/Desktop/poly2/poly2_Tibia4_coll_11.dae" />
            </geometry>
        </collision>
        <collision name="Tibia4">
            <origin rpy="1.472774 2.285659 2.017877" xyz="-0.033693 -0.024713 -0.003985" />
            <geometry>
                <mesh filename="file://C:/Users/hp/Desktop/poly2/poly2_Tibia4_coll_12.dae" />
            </geometry>
        </collision>
        <collision name="Tibia4">
            <origin rpy="1.472774 2.285659 2.017877" xyz="-0.033693 -0.024713 -0.003985" />
            <geometry>
                <mesh filename="file://C:/Users/hp/Desktop/poly2/poly2_Tibia4_coll_13.dae" />
            </geometry>
        </collision>
        <collision name="Tibia4">
            <origin rpy="1.472774 2.285659 2.017877" xyz="-0.033693 -0.024713 -0.003985" />
            <geometry>
                <mesh filename="file://C:/Users/hp/Desktop/poly2/poly2_Tibia4_coll_14.dae" />
            </geometry>
        </collision>
        <collision name="Tibia4">
            <origin rpy="1.472774 2.285659 2.017877" xyz="-0.033693 -0.024713 -0.003985" />
            <geometry>
                <mesh filename="file://C:/Users/hp/Desktop/poly2/poly2_Tibia4_coll_15.dae" />
            </geometry>
        </collision>
        <collision name="Tibia4">
            <origin rpy="1.472774 2.285659 2.017877" xyz="-0.033693 -0.024713 -0.003985" />
            <geometry>
                <mesh filename="file://C:/Users/hp/Desktop/poly2/poly2_Tibia4_coll_16.dae" />
            </geometry>
        </collision>
        <collision name="Tibia4">
            <origin rpy="1.472774 2.285659 2.017877" xyz="-0.033693 -0.024713 -0.003985" />
            <geometry>
                <mesh filename="file://C:/Users/hp/Desktop/poly2/poly2_Tibia4_coll_17.dae" />
            </geometry>
        </collision>
        <collision name="Tibia4">
            <origin rpy="1.472774 2.285659 2.017877" xyz="-0.033693 -0.024713 -0.003985" />
            <geometry>
                <mesh filename="file://C:/Users/hp/Desktop/poly2/poly2_Tibia4_coll_18.dae" />
            </geometry>
        </collision>
        <collision name="Tibia4">
            <origin rpy="1.472774 2.285659 2.017877" xyz="-0.033693 -0.024713 -0.003985" />
            <geometry>
                <mesh filename="file://C:/Users/hp/Desktop/poly2/poly2_Tibia4_coll_19.dae" />
            </geometry>
        </collision>
        <collision name="Tibia4">
            <origin rpy="1.472774 2.285659 2.017877" xyz="-0.033693 -0.024713 -0.003985" />
            <geometry>
                <mesh filename="file://C:/Users/hp/Desktop/poly2/poly2_Tibia4_coll_20.dae" />
            </geometry>
        </collision>
        <collision name="Tibia4">
            <origin rpy="1.472774 2.285659 2.017877" xyz="-0.033693 -0.024713 -0.003985" />
            <geometry>
                <mesh filename="file://C:/Users/hp/Desktop/poly2/poly2_Tibia4_coll_21.dae" />
            </geometry>
        </collision>
        <collision name="Tibia4">
            <origin rpy="1.472774 2.285659 2.017877" xyz="-0.033693 -0.024713 -0.003985" />
            <geometry>
                <mesh filename="file://C:/Users/hp/Desktop/poly2/poly2_Tibia4_coll_22.dae" />
            </geometry>
        </collision>
        <collision name="Tibia4">
            <origin rpy="1.472774 2.285659 2.017877" xyz="-0.033693 -0.024713 -0.003985" />
            <geometry>
                <mesh filename="file://C:/Users/hp/Desktop/poly2/poly2_Tibia4_coll_23.dae" />
            </geometry>
        </collision>
        <collision name="Tibia4">
            <origin rpy="1.472774 2.285659 2.017877" xyz="-0.033693 -0.024713 -0.003985" />
            <geometry>
                <mesh filename="file://C:/Users/hp/Desktop/poly2/poly2_Tibia4_coll_24.dae" />
            </geometry>
        </collision>
        <collision name="Tibia4">
            <origin rpy="1.472774 2.285659 2.017877" xyz="-0.033693 -0.024713 -0.003985" />
            <geometry>
                <mesh filename="file://C:/Users/hp/Desktop/poly2/poly2_Tibia4_coll_25.dae" />
            </geometry>
        </collision>
        <collision name="Tibia4">
            <origin rpy="1.472774 2.285659 2.017877" xyz="-0.033693 -0.024713 -0.003985" />
            <geometry>
                <mesh filename="file://C:/Users/hp/Desktop/poly2/poly2_Tibia4_coll_26.dae" />
            </geometry>
        </collision>
        <collision name="Tibia4">
            <origin rpy="1.472774 2.285659 2.017877" xyz="-0.033693 -0.024713 -0.003985" />
            <geometry>
                <mesh filename="file://C:/Users/hp/Desktop/poly2/poly2_Tibia4_coll_27.dae" />
            </geometry>
        </collision>
        <visual name="TibiaC">
            <origin rpy="1.472774 2.285659 2.017877" xyz="-0.033693 -0.024713 -0.003985" />
            <geometry>
                <mesh filename="file://C:/Users/hp/Desktop/poly2/poly2_TibiaC_vis_1.dae" />
            </geometry>
            <material name="TibiaC_material">
                <color rgba="0.000000 0.000000 0.000000 1.0" />
            </material>
        </visual>
    </link>
    <joint name="Shoulder1" type="revolute">
        <axis xyz="0 0 1" />
        <limit upper="3.1415919211481" velocity="6.2831854820251" effort="2.5" lower="-3.141593560877" />
        <parent link="robot_base" />
        <child link="Case1" />
        <origin rpy="3.078568 1.588567 -0.083163" xyz="3.193513 -5.178169 0.192184" />
    </joint>
    <link name="Case1">
        <collision name="Case1">
            <origin rpy="-0.000000 3.141593 0.000001" xyz="0.000255 0.001198 -0.009000" />
            <geometry>
                <mesh filename="file://C:/Users/hp/Desktop/poly2/poly2_Case1_coll_1.dae" />
            </geometry>
        </collision>
        <collision name="Case1">
            <origin rpy="-0.000000 3.141593 0.000001" xyz="0.000255 0.001198 -0.009000" />
            <geometry>
                <mesh filename="file://C:/Users/hp/Desktop/poly2/poly2_Case1_coll_2.dae" />
            </geometry>
        </collision>
        <collision name="Case1">
            <origin rpy="-0.000000 3.141593 0.000001" xyz="0.000255 0.001198 -0.009000" />
            <geometry>
                <mesh filename="file://C:/Users/hp/Desktop/poly2/poly2_Case1_coll_3.dae" />
            </geometry>
        </collision>
        <collision name="Case1">
            <origin rpy="-0.000000 3.141593 0.000001" xyz="0.000255 0.001198 -0.009000" />
            <geometry>
                <mesh filename="file://C:/Users/hp/Desktop/poly2/poly2_Case1_coll_4.dae" />
            </geometry>
        </collision>
        <collision name="Case1">
            <origin rpy="-0.000000 3.141593 0.000001" xyz="0.000255 0.001198 -0.009000" />
            <geometry>
                <mesh filename="file://C:/Users/hp/Desktop/poly2/poly2_Case1_coll_5.dae" />
            </geometry>
        </collision>
        <collision name="Case1">
            <origin rpy="-0.000000 3.141593 0.000001" xyz="0.000255 0.001198 -0.009000" />
            <geometry>
                <mesh filename="file://C:/Users/hp/Desktop/poly2/poly2_Case1_coll_6.dae" />
            </geometry>
        </collision>
        <collision name="Case1">
            <origin rpy="-0.000000 3.141593 0.000001" xyz="0.000255 0.001198 -0.009000" />
            <geometry>
                <mesh filename="file://C:/Users/hp/Desktop/poly2/poly2_Case1_coll_7.dae" />
            </geometry>
        </collision>
        <collision name="Case1">
            <origin rpy="-0.000000 3.141593 0.000001" xyz="0.000255 0.001198 -0.009000" />
            <geometry>
                <mesh filename="file://C:/Users/hp/Desktop/poly2/poly2_Case1_coll_8.dae" />
            </geometry>
        </collision>
        <collision name="Case1">
            <origin rpy="-0.000000 3.141593 0.000001" xyz="0.000255 0.001198 -0.009000" />
            <geometry>
                <mesh filename="file://C:/Users/hp/Desktop/poly2/poly2_Case1_coll_9.dae" />
            </geometry>
        </collision>
        <collision name="Case1">
            <origin rpy="-0.000000 3.141593 0.000001" xyz="0.000255 0.001198 -0.009000" />
            <geometry>
                <mesh filename="file://C:/Users/hp/Desktop/poly2/poly2_Case1_coll_10.dae" />
            </geometry>
        </collision>
        <collision name="Case1">
            <origin rpy="-0.000000 3.141593 0.000001" xyz="0.000255 0.001198 -0.009000" />
            <geometry>
                <mesh filename="file://C:/Users/hp/Desktop/poly2/poly2_Case1_coll_11.dae" />
            </geometry>
        </collision>
        <collision name="Case1">
            <origin rpy="-0.000000 3.141593 0.000001" xyz="0.000255 0.001198 -0.009000" />
            <geometry>
                <mesh filename="file://C:/Users/hp/Desktop/poly2/poly2_Case1_coll_12.dae" />
            </geometry>
        </collision>
        <collision name="Case1">
            <origin rpy="-0.000000 3.141593 0.000001" xyz="0.000255 0.001198 -0.009000" />
            <geometry>
                <mesh filename="file://C:/Users/hp/Desktop/poly2/poly2_Case1_coll_13.dae" />
            </geometry>
        </collision>
        <collision name="Case1">
            <origin rpy="-0.000000 3.141593 0.000001" xyz="0.000255 0.001198 -0.009000" />
            <geometry>
                <mesh filename="file://C:/Users/hp/Desktop/poly2/poly2_Case1_coll_14.dae" />
            </geometry>
        </collision>
        <collision name="Case1">
            <origin rpy="-0.000000 3.141593 0.000001" xyz="0.000255 0.001198 -0.009000" />
            <geometry>
                <mesh filename="file://C:/Users/hp/Desktop/poly2/poly2_Case1_coll_15.dae" />
            </geometry>
        </collision>
        <visual name="CaseA">
            <origin rpy="-0.000000 3.141593 0.000001" xyz="0.000255 0.001198 -0.009000" />
            <geometry>
                <mesh filename="file://C:/Users/hp/Desktop/poly2/poly2_CaseA_vis_1.dae" />
            </geometry>
            <material name="CaseA_material">
                <color rgba="0.000000 0.000000 0.000000 1.0" />
            </material>
        </visual>
    </link>
    <joint name="Hip1" type="revolute">
        <axis xyz="0 0 1" />
        <limit upper="3.1509623369202" velocity="6.2831854820251" effort="2.5" lower="-3.1322231451049" />
        <parent link="Case1" />
        <child link="Femur1" />
        <origin rpy="1.570797 -1.570796 0.000000" xyz="-0.000000 0.005000 -0.041000" />
    </joint>
    <link name="Femur1">
        <collision name="Femur1">
            <origin rpy="-1.513971 4.553148 -2.691663" xyz="0.026693 -0.048463 0.033297" />
            <geometry>
                <mesh filename="file://C:/Users/hp/Desktop/poly2/poly2_Femur1_coll_1.dae" />
            </geometry>
        </collision>
        <collision name="Femur1">
            <origin rpy="-1.513971 4.553148 -2.691663" xyz="0.026693 -0.048463 0.033297" />
            <geometry>
                <mesh filename="file://C:/Users/hp/Desktop/poly2/poly2_Femur1_coll_2.dae" />
            </geometry>
        </collision>
        <collision name="Femur1">
            <origin rpy="-1.513971 4.553148 -2.691663" xyz="0.026693 -0.048463 0.033297" />
            <geometry>
                <mesh filename="file://C:/Users/hp/Desktop/poly2/poly2_Femur1_coll_3.dae" />
            </geometry>
        </collision>
        <collision name="Femur1">
            <origin rpy="-1.513971 4.553148 -2.691663" xyz="0.026693 -0.048463 0.033297" />
            <geometry>
                <mesh filename="file://C:/Users/hp/Desktop/poly2/poly2_Femur1_coll_4.dae" />
            </geometry>
        </collision>
        <collision name="Femur1">
            <origin rpy="-1.513971 4.553148 -2.691663" xyz="0.026693 -0.048463 0.033297" />
            <geometry>
                <mesh filename="file://C:/Users/hp/Desktop/poly2/poly2_Femur1_coll_5.dae" />
            </geometry>
        </collision>
        <collision name="Femur1">
            <origin rpy="-1.513971 4.553148 -2.691663" xyz="0.026693 -0.048463 0.033297" />
            <geometry>
                <mesh filename="file://C:/Users/hp/Desktop/poly2/poly2_Femur1_coll_6.dae" />
            </geometry>
        </collision>
        <collision name="Femur1">
            <origin rpy="-1.513971 4.553148 -2.691663" xyz="0.026693 -0.048463 0.033297" />
            <geometry>
                <mesh filename="file://C:/Users/hp/Desktop/poly2/poly2_Femur1_coll_7.dae" />
            </geometry>
        </collision>
        <collision name="Femur1">
            <origin rpy="-1.513971 4.553148 -2.691663" xyz="0.026693 -0.048463 0.033297" />
            <geometry>
                <mesh filename="file://C:/Users/hp/Desktop/poly2/poly2_Femur1_coll_8.dae" />
            </geometry>
        </collision>
        <collision name="Femur1">
            <origin rpy="-1.513971 4.553148 -2.691663" xyz="0.026693 -0.048463 0.033297" />
            <geometry>
                <mesh filename="file://C:/Users/hp/Desktop/poly2/poly2_Femur1_coll_9.dae" />
            </geometry>
        </collision>
        <collision name="Femur1">
            <origin rpy="-1.513971 4.553148 -2.691663" xyz="0.026693 -0.048463 0.033297" />
            <geometry>
                <mesh filename="file://C:/Users/hp/Desktop/poly2/poly2_Femur1_coll_10.dae" />
            </geometry>
        </collision>
        <collision name="Femur1">
            <origin rpy="-1.513971 4.553148 -2.691663" xyz="0.026693 -0.048463 0.033297" />
            <geometry>
                <mesh filename="file://C:/Users/hp/Desktop/poly2/poly2_Femur1_coll_11.dae" />
            </geometry>
        </collision>
        <collision name="Femur1">
            <origin rpy="-1.513971 4.553148 -2.691663" xyz="0.026693 -0.048463 0.033297" />
            <geometry>
                <mesh filename="file://C:/Users/hp/Desktop/poly2/poly2_Femur1_coll_12.dae" />
            </geometry>
        </collision>
        <collision name="Femur1">
            <origin rpy="-1.513971 4.553148 -2.691663" xyz="0.026693 -0.048463 0.033297" />
            <geometry>
                <mesh filename="file://C:/Users/hp/Desktop/poly2/poly2_Femur1_coll_13.dae" />
            </geometry>
        </collision>
        <collision name="Femur1">
            <origin rpy="-1.513971 4.553148 -2.691663" xyz="0.026693 -0.048463 0.033297" />
            <geometry>
                <mesh filename="file://C:/Users/hp/Desktop/poly2/poly2_Femur1_coll_14.dae" />
            </geometry>
        </collision>
        <collision name="Femur1">
            <origin rpy="-1.513971 4.553148 -2.691663" xyz="0.026693 -0.048463 0.033297" />
            <geometry>
                <mesh filename="file://C:/Users/hp/Desktop/poly2/poly2_Femur1_coll_15.dae" />
            </geometry>
        </collision>
        <collision name="Femur1">
            <origin rpy="-1.513971 4.553148 -2.691663" xyz="0.026693 -0.048463 0.033297" />
            <geometry>
                <mesh filename="file://C:/Users/hp/Desktop/poly2/poly2_Femur1_coll_16.dae" />
            </geometry>
        </collision>
        <collision name="Femur1">
            <origin rpy="-1.513971 4.553148 -2.691663" xyz="0.026693 -0.048463 0.033297" />
            <geometry>
                <mesh filename="file://C:/Users/hp/Desktop/poly2/poly2_Femur1_coll_17.dae" />
            </geometry>
        </collision>
        <collision name="Femur1">
            <origin rpy="-1.513971 4.553148 -2.691663" xyz="0.026693 -0.048463 0.033297" />
            <geometry>
                <mesh filename="file://C:/Users/hp/Desktop/poly2/poly2_Femur1_coll_18.dae" />
            </geometry>
        </collision>
        <visual name="FemurA">
            <origin rpy="-1.513971 4.553148 -2.691663" xyz="0.026693 -0.048463 0.033297" />
            <geometry>
                <mesh filename="file://C:/Users/hp/Desktop/poly2/poly2_FemurA_vis_1.dae" />
            </geometry>
            <material name="FemurA_material">
                <color rgba="0.000000 0.000000 0.000000 1.0" />
            </material>
        </visual>
    </link>
    <joint name="Knee1" type="revolute">
        <axis xyz="0 0 1" />
        <limit upper="3.1194381881505" velocity="6.2831854820251" effort="2.5" lower="-3.1637472938746" />
        <parent link="Femur1" />
        <child link="Tibia1" />
        <origin rpy="-3.141593 3.141593 3.132223" xyz="0.077166 -0.104939 0.032297" />
    </joint>
    <link name="Tibia1">
        <collision name="Tibia1">
            <origin rpy="1.461268 2.301363 2.009598" xyz="-0.034673 -0.024706 -0.002965" />
            <geometry>
                <mesh filename="file://C:/Users/hp/Desktop/poly2/poly2_Tibia1_coll_1.dae" />
            </geometry>
        </collision>
        <collision name="Tibia1">
            <origin rpy="1.461268 2.301363 2.009598" xyz="-0.034673 -0.024706 -0.002965" />
            <geometry>
                <mesh filename="file://C:/Users/hp/Desktop/poly2/poly2_Tibia1_coll_2.dae" />
            </geometry>
        </collision>
        <collision name="Tibia1">
            <origin rpy="1.461268 2.301363 2.009598" xyz="-0.034673 -0.024706 -0.002965" />
            <geometry>
                <mesh filename="file://C:/Users/hp/Desktop/poly2/poly2_Tibia1_coll_3.dae" />
            </geometry>
        </collision>
        <collision name="Tibia1">
            <origin rpy="1.461268 2.301363 2.009598" xyz="-0.034673 -0.024706 -0.002965" />
            <geometry>
                <mesh filename="file://C:/Users/hp/Desktop/poly2/poly2_Tibia1_coll_4.dae" />
            </geometry>
        </collision>
        <collision name="Tibia1">
            <origin rpy="1.461268 2.301363 2.009598" xyz="-0.034673 -0.024706 -0.002965" />
            <geometry>
                <mesh filename="file://C:/Users/hp/Desktop/poly2/poly2_Tibia1_coll_5.dae" />
            </geometry>
        </collision>
        <collision name="Tibia1">
            <origin rpy="1.461268 2.301363 2.009598" xyz="-0.034673 -0.024706 -0.002965" />
            <geometry>
                <mesh filename="file://C:/Users/hp/Desktop/poly2/poly2_Tibia1_coll_6.dae" />
            </geometry>
        </collision>
        <collision name="Tibia1">
            <origin rpy="1.461268 2.301363 2.009598" xyz="-0.034673 -0.024706 -0.002965" />
            <geometry>
                <mesh filename="file://C:/Users/hp/Desktop/poly2/poly2_Tibia1_coll_7.dae" />
            </geometry>
        </collision>
        <collision name="Tibia1">
            <origin rpy="1.461268 2.301363 2.009598" xyz="-0.034673 -0.024706 -0.002965" />
            <geometry>
                <mesh filename="file://C:/Users/hp/Desktop/poly2/poly2_Tibia1_coll_8.dae" />
            </geometry>
        </collision>
        <collision name="Tibia1">
            <origin rpy="1.461268 2.301363 2.009598" xyz="-0.034673 -0.024706 -0.002965" />
            <geometry>
                <mesh filename="file://C:/Users/hp/Desktop/poly2/poly2_Tibia1_coll_9.dae" />
            </geometry>
        </collision>
        <collision name="Tibia1">
            <origin rpy="1.461268 2.301363 2.009598" xyz="-0.034673 -0.024706 -0.002965" />
            <geometry>
                <mesh filename="file://C:/Users/hp/Desktop/poly2/poly2_Tibia1_coll_10.dae" />
            </geometry>
        </collision>
        <collision name="Tibia1">
            <origin rpy="1.461268 2.301363 2.009598" xyz="-0.034673 -0.024706 -0.002965" />
            <geometry>
                <mesh filename="file://C:/Users/hp/Desktop/poly2/poly2_Tibia1_coll_11.dae" />
            </geometry>
        </collision>
        <collision name="Tibia1">
            <origin rpy="1.461268 2.301363 2.009598" xyz="-0.034673 -0.024706 -0.002965" />
            <geometry>
                <mesh filename="file://C:/Users/hp/Desktop/poly2/poly2_Tibia1_coll_12.dae" />
            </geometry>
        </collision>
        <collision name="Tibia1">
            <origin rpy="1.461268 2.301363 2.009598" xyz="-0.034673 -0.024706 -0.002965" />
            <geometry>
                <mesh filename="file://C:/Users/hp/Desktop/poly2/poly2_Tibia1_coll_13.dae" />
            </geometry>
        </collision>
        <collision name="Tibia1">
            <origin rpy="1.461268 2.301363 2.009598" xyz="-0.034673 -0.024706 -0.002965" />
            <geometry>
                <mesh filename="file://C:/Users/hp/Desktop/poly2/poly2_Tibia1_coll_14.dae" />
            </geometry>
        </collision>
        <collision name="Tibia1">
            <origin rpy="1.461268 2.301363 2.009598" xyz="-0.034673 -0.024706 -0.002965" />
            <geometry>
                <mesh filename="file://C:/Users/hp/Desktop/poly2/poly2_Tibia1_coll_15.dae" />
            </geometry>
        </collision>
        <collision name="Tibia1">
            <origin rpy="1.461268 2.301363 2.009598" xyz="-0.034673 -0.024706 -0.002965" />
            <geometry>
                <mesh filename="file://C:/Users/hp/Desktop/poly2/poly2_Tibia1_coll_16.dae" />
            </geometry>
        </collision>
        <collision name="Tibia1">
            <origin rpy="1.461268 2.301363 2.009598" xyz="-0.034673 -0.024706 -0.002965" />
            <geometry>
                <mesh filename="file://C:/Users/hp/Desktop/poly2/poly2_Tibia1_coll_17.dae" />
            </geometry>
        </collision>
        <collision name="Tibia1">
            <origin rpy="1.461268 2.301363 2.009598" xyz="-0.034673 -0.024706 -0.002965" />
            <geometry>
                <mesh filename="file://C:/Users/hp/Desktop/poly2/poly2_Tibia1_coll_18.dae" />
            </geometry>
        </collision>
        <collision name="Tibia1">
            <origin rpy="1.461268 2.301363 2.009598" xyz="-0.034673 -0.024706 -0.002965" />
            <geometry>
                <mesh filename="file://C:/Users/hp/Desktop/poly2/poly2_Tibia1_coll_19.dae" />
            </geometry>
        </collision>
        <collision name="Tibia1">
            <origin rpy="1.461268 2.301363 2.009598" xyz="-0.034673 -0.024706 -0.002965" />
            <geometry>
                <mesh filename="file://C:/Users/hp/Desktop/poly2/poly2_Tibia1_coll_20.dae" />
            </geometry>
        </collision>
        <collision name="Tibia1">
            <origin rpy="1.461268 2.301363 2.009598" xyz="-0.034673 -0.024706 -0.002965" />
            <geometry>
                <mesh filename="file://C:/Users/hp/Desktop/poly2/poly2_Tibia1_coll_21.dae" />
            </geometry>
        </collision>
        <collision name="Tibia1">
            <origin rpy="1.461268 2.301363 2.009598" xyz="-0.034673 -0.024706 -0.002965" />
            <geometry>
                <mesh filename="file://C:/Users/hp/Desktop/poly2/poly2_Tibia1_coll_22.dae" />
            </geometry>
        </collision>
        <collision name="Tibia1">
            <origin rpy="1.461268 2.301363 2.009598" xyz="-0.034673 -0.024706 -0.002965" />
            <geometry>
                <mesh filename="file://C:/Users/hp/Desktop/poly2/poly2_Tibia1_coll_23.dae" />
            </geometry>
        </collision>
        <collision name="Tibia1">
            <origin rpy="1.461268 2.301363 2.009598" xyz="-0.034673 -0.024706 -0.002965" />
            <geometry>
                <mesh filename="file://C:/Users/hp/Desktop/poly2/poly2_Tibia1_coll_24.dae" />
            </geometry>
        </collision>
        <collision name="Tibia1">
            <origin rpy="1.461268 2.301363 2.009598" xyz="-0.034673 -0.024706 -0.002965" />
            <geometry>
                <mesh filename="file://C:/Users/hp/Desktop/poly2/poly2_Tibia1_coll_25.dae" />
            </geometry>
        </collision>
        <collision name="Tibia1">
            <origin rpy="1.461268 2.301363 2.009598" xyz="-0.034673 -0.024706 -0.002965" />
            <geometry>
                <mesh filename="file://C:/Users/hp/Desktop/poly2/poly2_Tibia1_coll_26.dae" />
            </geometry>
        </collision>
        <collision name="Tibia1">
            <origin rpy="1.461268 2.301363 2.009598" xyz="-0.034673 -0.024706 -0.002965" />
            <geometry>
                <mesh filename="file://C:/Users/hp/Desktop/poly2/poly2_Tibia1_coll_27.dae" />
            </geometry>
        </collision>
        <visual name="TibiaA">
            <origin rpy="1.461268 2.301363 2.009598" xyz="-0.034673 -0.024706 -0.002965" />
            <geometry>
                <mesh filename="file://C:/Users/hp/Desktop/poly2/poly2_TibiaA_vis_1.dae" />
            </geometry>
            <material name="TibiaA_material">
                <color rgba="0.000000 0.000000 0.000000 1.0" />
            </material>
        </visual>
    </link>
    <joint name="Shoulder3" type="revolute">
        <axis xyz="0 0 1" />
        <limit upper="3.1415929746547" velocity="6.2831854820251" effort="2.5" lower="-3.1415925073705" />
        <parent link="robot_base" />
        <child link="Case3" />
        <origin rpy="3.078568 1.588567 -0.083163" xyz="2.950617 -5.321309 0.196275" />
    </joint>
    <link name="Case3">
        <collision name="Case3">
            <origin rpy="0.000000 3.141593 3.141592" xyz="0.000255 0.000198 -0.011000" />
            <geometry>
                <mesh filename="file://C:/Users/hp/Desktop/poly2/poly2_Case3_coll_1.dae" />
            </geometry>
        </collision>
        <collision name="Case3">
            <origin rpy="0.000000 3.141593 3.141592" xyz="0.000255 0.000198 -0.011000" />
            <geometry>
                <mesh filename="file://C:/Users/hp/Desktop/poly2/poly2_Case3_coll_2.dae" />
            </geometry>
        </collision>
        <collision name="Case3">
            <origin rpy="0.000000 3.141593 3.141592" xyz="0.000255 0.000198 -0.011000" />
            <geometry>
                <mesh filename="file://C:/Users/hp/Desktop/poly2/poly2_Case3_coll_3.dae" />
            </geometry>
        </collision>
        <collision name="Case3">
            <origin rpy="0.000000 3.141593 3.141592" xyz="0.000255 0.000198 -0.011000" />
            <geometry>
                <mesh filename="file://C:/Users/hp/Desktop/poly2/poly2_Case3_coll_4.dae" />
            </geometry>
        </collision>
        <collision name="Case3">
            <origin rpy="0.000000 3.141593 3.141592" xyz="0.000255 0.000198 -0.011000" />
            <geometry>
                <mesh filename="file://C:/Users/hp/Desktop/poly2/poly2_Case3_coll_5.dae" />
            </geometry>
        </collision>
        <collision name="Case3">
            <origin rpy="0.000000 3.141593 3.141592" xyz="0.000255 0.000198 -0.011000" />
            <geometry>
                <mesh filename="file://C:/Users/hp/Desktop/poly2/poly2_Case3_coll_6.dae" />
            </geometry>
        </collision>
        <collision name="Case3">
            <origin rpy="0.000000 3.141593 3.141592" xyz="0.000255 0.000198 -0.011000" />
            <geometry>
                <mesh filename="file://C:/Users/hp/Desktop/poly2/poly2_Case3_coll_7.dae" />
            </geometry>
        </collision>
        <collision name="Case3">
            <origin rpy="0.000000 3.141593 3.141592" xyz="0.000255 0.000198 -0.011000" />
            <geometry>
                <mesh filename="file://C:/Users/hp/Desktop/poly2/poly2_Case3_coll_8.dae" />
            </geometry>
        </collision>
        <collision name="Case3">
            <origin rpy="0.000000 3.141593 3.141592" xyz="0.000255 0.000198 -0.011000" />
            <geometry>
                <mesh filename="file://C:/Users/hp/Desktop/poly2/poly2_Case3_coll_9.dae" />
            </geometry>
        </collision>
        <collision name="Case3">
            <origin rpy="0.000000 3.141593 3.141592" xyz="0.000255 0.000198 -0.011000" />
            <geometry>
                <mesh filename="file://C:/Users/hp/Desktop/poly2/poly2_Case3_coll_10.dae" />
            </geometry>
        </collision>
        <collision name="Case3">
            <origin rpy="0.000000 3.141593 3.141592" xyz="0.000255 0.000198 -0.011000" />
            <geometry>
                <mesh filename="file://C:/Users/hp/Desktop/poly2/poly2_Case3_coll_11.dae" />
            </geometry>
        </collision>
        <collision name="Case3">
            <origin rpy="0.000000 3.141593 3.141592" xyz="0.000255 0.000198 -0.011000" />
            <geometry>
                <mesh filename="file://C:/Users/hp/Desktop/poly2/poly2_Case3_coll_12.dae" />
            </geometry>
        </collision>
        <collision name="Case3">
            <origin rpy="0.000000 3.141593 3.141592" xyz="0.000255 0.000198 -0.011000" />
            <geometry>
                <mesh filename="file://C:/Users/hp/Desktop/poly2/poly2_Case3_coll_13.dae" />
            </geometry>
        </collision>
        <collision name="Case3">
            <origin rpy="0.000000 3.141593 3.141592" xyz="0.000255 0.000198 -0.011000" />
            <geometry>
                <mesh filename="file://C:/Users/hp/Desktop/poly2/poly2_Case3_coll_14.dae" />
            </geometry>
        </collision>
        <collision name="Case3">
            <origin rpy="0.000000 3.141593 3.141592" xyz="0.000255 0.000198 -0.011000" />
            <geometry>
                <mesh filename="file://C:/Users/hp/Desktop/poly2/poly2_Case3_coll_15.dae" />
            </geometry>
        </collision>
        <visual name="CaseC">
            <origin rpy="0.000000 3.141593 3.141592" xyz="0.000255 0.000198 -0.011000" />
            <geometry>
                <mesh filename="file://C:/Users/hp/Desktop/poly2/poly2_CaseC_vis_1.dae" />
            </geometry>
            <material name="CaseC_material">
                <color rgba="0.000000 0.000000 0.000000 1.0" />
            </material>
        </visual>
    </link>
    <joint name="Hip3" type="revolute">
        <axis xyz="0 0 1" />
        <limit upper="3.1510525476187" velocity="6.2831854820251" effort="2.5" lower="-3.1321329344064" />
        <parent link="Case3" />
        <child link="Femur3" />
        <origin rpy="1.570796 -1.570796 0.000000" xyz="0.000000 0.005000 0.021000" />
    </joint>
    <link name="Femur3">
        <collision name="Femur3">
            <origin rpy="2.034291 1.570798 1.848222" xyz="0.029764 -0.040494 -0.024703" />
            <geometry>
                <mesh filename="file://C:/Users/hp/Desktop/poly2/poly2_Femur3_coll_1.dae" />
            </geometry>
        </collision>
        <collision name="Femur3">
            <origin rpy="2.034291 1.570798 1.848222" xyz="0.029764 -0.040494 -0.024703" />
            <geometry>
                <mesh filename="file://C:/Users/hp/Desktop/poly2/poly2_Femur3_coll_2.dae" />
            </geometry>
        </collision>
        <collision name="Femur3">
            <origin rpy="2.034291 1.570798 1.848222" xyz="0.029764 -0.040494 -0.024703" />
            <geometry>
                <mesh filename="file://C:/Users/hp/Desktop/poly2/poly2_Femur3_coll_3.dae" />
            </geometry>
        </collision>
        <collision name="Femur3">
            <origin rpy="2.034291 1.570798 1.848222" xyz="0.029764 -0.040494 -0.024703" />
            <geometry>
                <mesh filename="file://C:/Users/hp/Desktop/poly2/poly2_Femur3_coll_4.dae" />
            </geometry>
        </collision>
        <collision name="Femur3">
            <origin rpy="2.034291 1.570798 1.848222" xyz="0.029764 -0.040494 -0.024703" />
            <geometry>
                <mesh filename="file://C:/Users/hp/Desktop/poly2/poly2_Femur3_coll_5.dae" />
            </geometry>
        </collision>
        <collision name="Femur3">
            <origin rpy="2.034291 1.570798 1.848222" xyz="0.029764 -0.040494 -0.024703" />
            <geometry>
                <mesh filename="file://C:/Users/hp/Desktop/poly2/poly2_Femur3_coll_6.dae" />
            </geometry>
        </collision>
        <collision name="Femur3">
            <origin rpy="2.034291 1.570798 1.848222" xyz="0.029764 -0.040494 -0.024703" />
            <geometry>
                <mesh filename="file://C:/Users/hp/Desktop/poly2/poly2_Femur3_coll_7.dae" />
            </geometry>
        </collision>
        <collision name="Femur3">
            <origin rpy="2.034291 1.570798 1.848222" xyz="0.029764 -0.040494 -0.024703" />
            <geometry>
                <mesh filename="file://C:/Users/hp/Desktop/poly2/poly2_Femur3_coll_8.dae" />
            </geometry>
        </collision>
        <collision name="Femur3">
            <origin rpy="2.034291 1.570798 1.848222" xyz="0.029764 -0.040494 -0.024703" />
            <geometry>
                <mesh filename="file://C:/Users/hp/Desktop/poly2/poly2_Femur3_coll_9.dae" />
            </geometry>
        </collision>
        <visual name="FemurC">
            <origin rpy="2.019700 1.570798 1.833631" xyz="0.029764 -0.040494 -0.024703" />
            <geometry>
                <mesh filename="file://C:/Users/hp/Desktop/poly2/poly2_FemurC_vis_1.dae" />
            </geometry>
            <material name="FemurC_material">
                <color rgba="0.000000 0.000000 0.000000 1.0" />
            </material>
        </visual>
    </link>
    <joint name="Knee3" type="revolute">
        <axis xyz="0 0 1" />
        <limit upper="3.1192252002656" velocity="6.2831854820251" effort="2.5" lower="-3.1639602817595" />
        <parent link="Femur3" />
        <child link="Tibia3" />
        <origin rpy="-3.141593 3.141593 3.132133" xyz="0.075156 -0.104927 -0.023703" />
    </joint>
    <link name="Tibia3">
        <collision name="Tibia3">
            <origin rpy="1.472774 2.285659 2.017967" xyz="-0.033671 -0.024818 -0.005063" />
            <geometry>
                <mesh filename="file://C:/Users/hp/Desktop/poly2/poly2_Tibia3_coll_1.dae" />
            </geometry>
        </collision>
        <collision name="Tibia3">
            <origin rpy="1.472774 2.285659 2.017967" xyz="-0.033671 -0.024818 -0.005063" />
            <geometry>
                <mesh filename="file://C:/Users/hp/Desktop/poly2/poly2_Tibia3_coll_2.dae" />
            </geometry>
        </collision>
        <collision name="Tibia3">
            <origin rpy="1.472774 2.285659 2.017967" xyz="-0.033671 -0.024818 -0.005063" />
            <geometry>
                <mesh filename="file://C:/Users/hp/Desktop/poly2/poly2_Tibia3_coll_3.dae" />
            </geometry>
        </collision>
        <collision name="Tibia3">
            <origin rpy="1.472774 2.285659 2.017967" xyz="-0.033671 -0.024818 -0.005063" />
            <geometry>
                <mesh filename="file://C:/Users/hp/Desktop/poly2/poly2_Tibia3_coll_4.dae" />
            </geometry>
        </collision>
        <collision name="Tibia3">
            <origin rpy="1.472774 2.285659 2.017967" xyz="-0.033671 -0.024818 -0.005063" />
            <geometry>
                <mesh filename="file://C:/Users/hp/Desktop/poly2/poly2_Tibia3_coll_5.dae" />
            </geometry>
        </collision>
        <collision name="Tibia3">
            <origin rpy="1.472774 2.285659 2.017967" xyz="-0.033671 -0.024818 -0.005063" />
            <geometry>
                <mesh filename="file://C:/Users/hp/Desktop/poly2/poly2_Tibia3_coll_6.dae" />
            </geometry>
        </collision>
        <collision name="Tibia3">
            <origin rpy="1.472774 2.285659 2.017967" xyz="-0.033671 -0.024818 -0.005063" />
            <geometry>
                <mesh filename="file://C:/Users/hp/Desktop/poly2/poly2_Tibia3_coll_7.dae" />
            </geometry>
        </collision>
        <collision name="Tibia3">
            <origin rpy="1.472774 2.285659 2.017967" xyz="-0.033671 -0.024818 -0.005063" />
            <geometry>
                <mesh filename="file://C:/Users/hp/Desktop/poly2/poly2_Tibia3_coll_8.dae" />
            </geometry>
        </collision>
        <collision name="Tibia3">
            <origin rpy="1.472774 2.285659 2.017967" xyz="-0.033671 -0.024818 -0.005063" />
            <geometry>
                <mesh filename="file://C:/Users/hp/Desktop/poly2/poly2_Tibia3_coll_9.dae" />
            </geometry>
        </collision>
        <collision name="Tibia3">
            <origin rpy="1.472774 2.285659 2.017967" xyz="-0.033671 -0.024818 -0.005063" />
            <geometry>
                <mesh filename="file://C:/Users/hp/Desktop/poly2/poly2_Tibia3_coll_10.dae" />
            </geometry>
        </collision>
        <collision name="Tibia3">
            <origin rpy="1.472774 2.285659 2.017967" xyz="-0.033671 -0.024818 -0.005063" />
            <geometry>
                <mesh filename="file://C:/Users/hp/Desktop/poly2/poly2_Tibia3_coll_11.dae" />
            </geometry>
        </collision>
        <collision name="Tibia3">
            <origin rpy="1.472774 2.285659 2.017967" xyz="-0.033671 -0.024818 -0.005063" />
            <geometry>
                <mesh filename="file://C:/Users/hp/Desktop/poly2/poly2_Tibia3_coll_12.dae" />
            </geometry>
        </collision>
        <collision name="Tibia3">
            <origin rpy="1.472774 2.285659 2.017967" xyz="-0.033671 -0.024818 -0.005063" />
            <geometry>
                <mesh filename="file://C:/Users/hp/Desktop/poly2/poly2_Tibia3_coll_13.dae" />
            </geometry>
        </collision>
        <collision name="Tibia3">
            <origin rpy="1.472774 2.285659 2.017967" xyz="-0.033671 -0.024818 -0.005063" />
            <geometry>
                <mesh filename="file://C:/Users/hp/Desktop/poly2/poly2_Tibia3_coll_14.dae" />
            </geometry>
        </collision>
        <collision name="Tibia3">
            <origin rpy="1.472774 2.285659 2.017967" xyz="-0.033671 -0.024818 -0.005063" />
            <geometry>
                <mesh filename="file://C:/Users/hp/Desktop/poly2/poly2_Tibia3_coll_15.dae" />
            </geometry>
        </collision>
        <collision name="Tibia3">
            <origin rpy="1.472774 2.285659 2.017967" xyz="-0.033671 -0.024818 -0.005063" />
            <geometry>
                <mesh filename="file://C:/Users/hp/Desktop/poly2/poly2_Tibia3_coll_16.dae" />
            </geometry>
        </collision>
        <collision name="Tibia3">
            <origin rpy="1.472774 2.285659 2.017967" xyz="-0.033671 -0.024818 -0.005063" />
            <geometry>
                <mesh filename="file://C:/Users/hp/Desktop/poly2/poly2_Tibia3_coll_17.dae" />
            </geometry>
        </collision>
        <collision name="Tibia3">
            <origin rpy="1.472774 2.285659 2.017967" xyz="-0.033671 -0.024818 -0.005063" />
            <geometry>
                <mesh filename="file://C:/Users/hp/Desktop/poly2/poly2_Tibia3_coll_18.dae" />
            </geometry>
        </collision>
        <collision name="Tibia3">
            <origin rpy="1.472774 2.285659 2.017967" xyz="-0.033671 -0.024818 -0.005063" />
            <geometry>
                <mesh filename="file://C:/Users/hp/Desktop/poly2/poly2_Tibia3_coll_19.dae" />
            </geometry>
        </collision>
        <collision name="Tibia3">
            <origin rpy="1.472774 2.285659 2.017967" xyz="-0.033671 -0.024818 -0.005063" />
            <geometry>
                <mesh filename="file://C:/Users/hp/Desktop/poly2/poly2_Tibia3_coll_20.dae" />
            </geometry>
        </collision>
        <collision name="Tibia3">
            <origin rpy="1.472774 2.285659 2.017967" xyz="-0.033671 -0.024818 -0.005063" />
            <geometry>
                <mesh filename="file://C:/Users/hp/Desktop/poly2/poly2_Tibia3_coll_21.dae" />
            </geometry>
        </collision>
        <collision name="Tibia3">
            <origin rpy="1.472774 2.285659 2.017967" xyz="-0.033671 -0.024818 -0.005063" />
            <geometry>
                <mesh filename="file://C:/Users/hp/Desktop/poly2/poly2_Tibia3_coll_22.dae" />
            </geometry>
        </collision>
        <collision name="Tibia3">
            <origin rpy="1.472774 2.285659 2.017967" xyz="-0.033671 -0.024818 -0.005063" />
            <geometry>
                <mesh filename="file://C:/Users/hp/Desktop/poly2/poly2_Tibia3_coll_23.dae" />
            </geometry>
        </collision>
        <collision name="Tibia3">
            <origin rpy="1.472774 2.285659 2.017967" xyz="-0.033671 -0.024818 -0.005063" />
            <geometry>
                <mesh filename="file://C:/Users/hp/Desktop/poly2/poly2_Tibia3_coll_24.dae" />
            </geometry>
        </collision>
        <collision name="Tibia3">
            <origin rpy="1.472774 2.285659 2.017967" xyz="-0.033671 -0.024818 -0.005063" />
            <geometry>
                <mesh filename="file://C:/Users/hp/Desktop/poly2/poly2_Tibia3_coll_25.dae" />
            </geometry>
        </collision>
        <collision name="Tibia3">
            <origin rpy="1.472774 2.285659 2.017967" xyz="-0.033671 -0.024818 -0.005063" />
            <geometry>
                <mesh filename="file://C:/Users/hp/Desktop/poly2/poly2_Tibia3_coll_26.dae" />
            </geometry>
        </collision>
        <collision name="Tibia3">
            <origin rpy="1.472774 2.285659 2.017967" xyz="-0.033671 -0.024818 -0.005063" />
            <geometry>
                <mesh filename="file://C:/Users/hp/Desktop/poly2/poly2_Tibia3_coll_27.dae" />
            </geometry>
        </collision>
        <visual name="TibiaC">
            <origin rpy="1.472774 2.285659 2.017967" xyz="-0.033671 -0.024818 -0.005063" />
            <geometry>
                <mesh filename="file://C:/Users/hp/Desktop/poly2/poly2_TibiaC_vis_1.dae" />
            </geometry>
            <material name="TibiaC_material">
                <color rgba="0.000000 0.000000 0.000000 1.0" />
            </material>
        </visual>
    </link>
    <joint name="Shoulder2" type="revolute">
        <axis xyz="0 0 1" />
        <limit upper="3.1415928265861" velocity="6.2831854820251" effort="2.5" lower="-3.1415926554391" />
        <parent link="robot_base" />
        <child link="Case2" />
        <origin rpy="3.078568 1.588567 -0.083163" xyz="3.190531 -5.326139 0.192018" />
    </joint>
    <link name="Case2">
        <collision name="Case2">
            <origin rpy="0.000000 3.141593 3.141593" xyz="0.000255 0.000198 -0.011000" />
            <geometry>
                <mesh filename="file://C:/Users/hp/Desktop/poly2/poly2_Case2_coll_1.dae" />
            </geometry>
        </collision>
        <collision name="Case2">
            <origin rpy="0.000000 3.141593 3.141593" xyz="0.000255 0.000198 -0.011000" />
            <geometry>
                <mesh filename="file://C:/Users/hp/Desktop/poly2/poly2_Case2_coll_2.dae" />
            </geometry>
        </collision>
        <collision name="Case2">
            <origin rpy="0.000000 3.141593 3.141593" xyz="0.000255 0.000198 -0.011000" />
            <geometry>
                <mesh filename="file://C:/Users/hp/Desktop/poly2/poly2_Case2_coll_3.dae" />
            </geometry>
        </collision>
        <collision name="Case2">
            <origin rpy="0.000000 3.141593 3.141593" xyz="0.000255 0.000198 -0.011000" />
            <geometry>
                <mesh filename="file://C:/Users/hp/Desktop/poly2/poly2_Case2_coll_4.dae" />
            </geometry>
        </collision>
        <collision name="Case2">
            <origin rpy="0.000000 3.141593 3.141593" xyz="0.000255 0.000198 -0.011000" />
            <geometry>
                <mesh filename="file://C:/Users/hp/Desktop/poly2/poly2_Case2_coll_5.dae" />
            </geometry>
        </collision>
        <collision name="Case2">
            <origin rpy="0.000000 3.141593 3.141593" xyz="0.000255 0.000198 -0.011000" />
            <geometry>
                <mesh filename="file://C:/Users/hp/Desktop/poly2/poly2_Case2_coll_6.dae" />
            </geometry>
        </collision>
        <collision name="Case2">
            <origin rpy="0.000000 3.141593 3.141593" xyz="0.000255 0.000198 -0.011000" />
            <geometry>
                <mesh filename="file://C:/Users/hp/Desktop/poly2/poly2_Case2_coll_7.dae" />
            </geometry>
        </collision>
        <collision name="Case2">
            <origin rpy="0.000000 3.141593 3.141593" xyz="0.000255 0.000198 -0.011000" />
            <geometry>
                <mesh filename="file://C:/Users/hp/Desktop/poly2/poly2_Case2_coll_8.dae" />
            </geometry>
        </collision>
        <collision name="Case2">
            <origin rpy="0.000000 3.141593 3.141593" xyz="0.000255 0.000198 -0.011000" />
            <geometry>
                <mesh filename="file://C:/Users/hp/Desktop/poly2/poly2_Case2_coll_9.dae" />
            </geometry>
        </collision>
        <collision name="Case2">
            <origin rpy="0.000000 3.141593 3.141593" xyz="0.000255 0.000198 -0.011000" />
            <geometry>
                <mesh filename="file://C:/Users/hp/Desktop/poly2/poly2_Case2_coll_10.dae" />
            </geometry>
        </collision>
        <collision name="Case2">
            <origin rpy="0.000000 3.141593 3.141593" xyz="0.000255 0.000198 -0.011000" />
            <geometry>
                <mesh filename="file://C:/Users/hp/Desktop/poly2/poly2_Case2_coll_11.dae" />
            </geometry>
        </collision>
        <collision name="Case2">
            <origin rpy="0.000000 3.141593 3.141593" xyz="0.000255 0.000198 -0.011000" />
            <geometry>
                <mesh filename="file://C:/Users/hp/Desktop/poly2/poly2_Case2_coll_12.dae" />
            </geometry>
        </collision>
        <collision name="Case2">
            <origin rpy="0.000000 3.141593 3.141593" xyz="0.000255 0.000198 -0.011000" />
            <geometry>
                <mesh filename="file://C:/Users/hp/Desktop/poly2/poly2_Case2_coll_13.dae" />
            </geometry>
        </collision>
        <collision name="Case2">
            <origin rpy="0.000000 3.141593 3.141593" xyz="0.000255 0.000198 -0.011000" />
            <geometry>
                <mesh filename="file://C:/Users/hp/Desktop/poly2/poly2_Case2_coll_14.dae" />
            </geometry>
        </collision>
        <collision name="Case2">
            <origin rpy="0.000000 3.141593 3.141593" xyz="0.000255 0.000198 -0.011000" />
            <geometry>
                <mesh filename="file://C:/Users/hp/Desktop/poly2/poly2_Case2_coll_15.dae" />
            </geometry>
        </collision>
        <visual name="CaseB">
            <origin rpy="0.000000 3.141593 3.141593" xyz="0.000255 0.000198 -0.011000" />
            <geometry>
                <mesh filename="file://C:/Users/hp/Desktop/poly2/poly2_CaseB_vis_1.dae" />
            </geometry>
            <material name="CaseB_material">
                <color rgba="0.000000 0.000000 0.000000 1.0" />
            </material>
        </visual>
    </link>
    <joint name="Hip2" type="revolute">
        <axis xyz="0 0 1" />
        <limit upper="3.1511756693944" velocity="6.2831854820251" effort="2.5" lower="-3.1320098126307" />
        <parent link="Case2" />
        <child link="Femur2" />
        <origin rpy="1.570796 -1.570796 0.000000" xyz="0.000000 0.005000 -0.041000" />
    </joint>
    <link name="Femur2">
        <collision name="Femur2">
            <origin rpy="2.034291 1.570798 1.848099" xyz="0.029759 -0.040498 -0.024703" />
            <geometry>
                <mesh filename="file://C:/Users/hp/Desktop/poly2/poly2_Femur2_coll_1.dae" />
            </geometry>
        </collision>
        <collision name="Femur2">
            <origin rpy="2.034291 1.570798 1.848099" xyz="0.029759 -0.040498 -0.024703" />
            <geometry>
                <mesh filename="file://C:/Users/hp/Desktop/poly2/poly2_Femur2_coll_2.dae" />
            </geometry>
        </collision>
        <collision name="Femur2">
            <origin rpy="2.034291 1.570798 1.848099" xyz="0.029759 -0.040498 -0.024703" />
            <geometry>
                <mesh filename="file://C:/Users/hp/Desktop/poly2/poly2_Femur2_coll_3.dae" />
            </geometry>
        </collision>
        <collision name="Femur2">
            <origin rpy="2.034291 1.570798 1.848099" xyz="0.029759 -0.040498 -0.024703" />
            <geometry>
                <mesh filename="file://C:/Users/hp/Desktop/poly2/poly2_Femur2_coll_4.dae" />
            </geometry>
        </collision>
        <collision name="Femur2">
            <origin rpy="2.034291 1.570798 1.848099" xyz="0.029759 -0.040498 -0.024703" />
            <geometry>
                <mesh filename="file://C:/Users/hp/Desktop/poly2/poly2_Femur2_coll_5.dae" />
            </geometry>
        </collision>
        <collision name="Femur2">
            <origin rpy="2.034291 1.570798 1.848099" xyz="0.029759 -0.040498 -0.024703" />
            <geometry>
                <mesh filename="file://C:/Users/hp/Desktop/poly2/poly2_Femur2_coll_6.dae" />
            </geometry>
        </collision>
        <collision name="Femur2">
            <origin rpy="2.034291 1.570798 1.848099" xyz="0.029759 -0.040498 -0.024703" />
            <geometry>
                <mesh filename="file://C:/Users/hp/Desktop/poly2/poly2_Femur2_coll_7.dae" />
            </geometry>
        </collision>
        <collision name="Femur2">
            <origin rpy="2.034291 1.570798 1.848099" xyz="0.029759 -0.040498 -0.024703" />
            <geometry>
                <mesh filename="file://C:/Users/hp/Desktop/poly2/poly2_Femur2_coll_8.dae" />
            </geometry>
        </collision>
        <collision name="Femur2">
            <origin rpy="2.034291 1.570798 1.848099" xyz="0.029759 -0.040498 -0.024703" />
            <geometry>
                <mesh filename="file://C:/Users/hp/Desktop/poly2/poly2_Femur2_coll_9.dae" />
            </geometry>
        </collision>
        <visual name="FemurB">
            <origin rpy="2.019700 1.570798 1.833508" xyz="0.029759 -0.040498 -0.024703" />
            <geometry>
                <mesh filename="file://C:/Users/hp/Desktop/poly2/poly2_FemurB_vis_1.dae" />
            </geometry>
            <material name="FemurB_material">
                <color rgba="0.000000 0.000000 0.000000 1.0" />
            </material>
        </visual>
    </link>
    <joint name="Knee2" type="revolute">
        <axis xyz="0 0 1" />
        <limit upper="3.1189339179546" velocity="6.2831854820251" effort="2.5" lower="-3.1642515640706" />
        <parent link="Femur2" />
        <child link="Tibia2" />
        <origin rpy="-3.141593 3.141593 3.132010" xyz="0.075143 -0.104936 -0.023703" />
    </joint>
    <link name="Tibia2">
        <collision name="Tibia2">
            <origin rpy="1.472774 2.285659 2.018090" xyz="-0.033774 -0.024458 -0.003982" />
            <geometry>
                <mesh filename="file://C:/Users/hp/Desktop/poly2/poly2_Tibia2_coll_1.dae" />
            </geometry>
        </collision>
        <collision name="Tibia2">
            <origin rpy="1.472774 2.285659 2.018090" xyz="-0.033774 -0.024458 -0.003982" />
            <geometry>
                <mesh filename="file://C:/Users/hp/Desktop/poly2/poly2_Tibia2_coll_2.dae" />
            </geometry>
        </collision>
        <collision name="Tibia2">
            <origin rpy="1.472774 2.285659 2.018090" xyz="-0.033774 -0.024458 -0.003982" />
            <geometry>
                <mesh filename="file://C:/Users/hp/Desktop/poly2/poly2_Tibia2_coll_3.dae" />
            </geometry>
        </collision>
        <collision name="Tibia2">
            <origin rpy="1.472774 2.285659 2.018090" xyz="-0.033774 -0.024458 -0.003982" />
            <geometry>
                <mesh filename="file://C:/Users/hp/Desktop/poly2/poly2_Tibia2_coll_4.dae" />
            </geometry>
        </collision>
        <collision name="Tibia2">
            <origin rpy="1.472774 2.285659 2.018090" xyz="-0.033774 -0.024458 -0.003982" />
            <geometry>
                <mesh filename="file://C:/Users/hp/Desktop/poly2/poly2_Tibia2_coll_5.dae" />
            </geometry>
        </collision>
        <collision name="Tibia2">
            <origin rpy="1.472774 2.285659 2.018090" xyz="-0.033774 -0.024458 -0.003982" />
            <geometry>
                <mesh filename="file://C:/Users/hp/Desktop/poly2/poly2_Tibia2_coll_6.dae" />
            </geometry>
        </collision>
        <collision name="Tibia2">
            <origin rpy="1.472774 2.285659 2.018090" xyz="-0.033774 -0.024458 -0.003982" />
            <geometry>
                <mesh filename="file://C:/Users/hp/Desktop/poly2/poly2_Tibia2_coll_7.dae" />
            </geometry>
        </collision>
        <collision name="Tibia2">
            <origin rpy="1.472774 2.285659 2.018090" xyz="-0.033774 -0.024458 -0.003982" />
            <geometry>
                <mesh filename="file://C:/Users/hp/Desktop/poly2/poly2_Tibia2_coll_8.dae" />
            </geometry>
        </collision>
        <collision name="Tibia2">
            <origin rpy="1.472774 2.285659 2.018090" xyz="-0.033774 -0.024458 -0.003982" />
            <geometry>
                <mesh filename="file://C:/Users/hp/Desktop/poly2/poly2_Tibia2_coll_9.dae" />
            </geometry>
        </collision>
        <collision name="Tibia2">
            <origin rpy="1.472774 2.285659 2.018090" xyz="-0.033774 -0.024458 -0.003982" />
            <geometry>
                <mesh filename="file://C:/Users/hp/Desktop/poly2/poly2_Tibia2_coll_10.dae" />
            </geometry>
        </collision>
        <collision name="Tibia2">
            <origin rpy="1.472774 2.285659 2.018090" xyz="-0.033774 -0.024458 -0.003982" />
            <geometry>
                <mesh filename="file://C:/Users/hp/Desktop/poly2/poly2_Tibia2_coll_11.dae" />
            </geometry>
        </collision>
        <collision name="Tibia2">
            <origin rpy="1.472774 2.285659 2.018090" xyz="-0.033774 -0.024458 -0.003982" />
            <geometry>
                <mesh filename="file://C:/Users/hp/Desktop/poly2/poly2_Tibia2_coll_12.dae" />
            </geometry>
        </collision>
        <collision name="Tibia2">
            <origin rpy="1.472774 2.285659 2.018090" xyz="-0.033774 -0.024458 -0.003982" />
            <geometry>
                <mesh filename="file://C:/Users/hp/Desktop/poly2/poly2_Tibia2_coll_13.dae" />
            </geometry>
        </collision>
        <collision name="Tibia2">
            <origin rpy="1.472774 2.285659 2.018090" xyz="-0.033774 -0.024458 -0.003982" />
            <geometry>
                <mesh filename="file://C:/Users/hp/Desktop/poly2/poly2_Tibia2_coll_14.dae" />
            </geometry>
        </collision>
        <collision name="Tibia2">
            <origin rpy="1.472774 2.285659 2.018090" xyz="-0.033774 -0.024458 -0.003982" />
            <geometry>
                <mesh filename="file://C:/Users/hp/Desktop/poly2/poly2_Tibia2_coll_15.dae" />
            </geometry>
        </collision>
        <collision name="Tibia2">
            <origin rpy="1.472774 2.285659 2.018090" xyz="-0.033774 -0.024458 -0.003982" />
            <geometry>
                <mesh filename="file://C:/Users/hp/Desktop/poly2/poly2_Tibia2_coll_16.dae" />
            </geometry>
        </collision>
        <collision name="Tibia2">
            <origin rpy="1.472774 2.285659 2.018090" xyz="-0.033774 -0.024458 -0.003982" />
            <geometry>
                <mesh filename="file://C:/Users/hp/Desktop/poly2/poly2_Tibia2_coll_17.dae" />
            </geometry>
        </collision>
        <collision name="Tibia2">
            <origin rpy="1.472774 2.285659 2.018090" xyz="-0.033774 -0.024458 -0.003982" />
            <geometry>
                <mesh filename="file://C:/Users/hp/Desktop/poly2/poly2_Tibia2_coll_18.dae" />
            </geometry>
        </collision>
        <collision name="Tibia2">
            <origin rpy="1.472774 2.285659 2.018090" xyz="-0.033774 -0.024458 -0.003982" />
            <geometry>
                <mesh filename="file://C:/Users/hp/Desktop/poly2/poly2_Tibia2_coll_19.dae" />
            </geometry>
        </collision>
        <collision name="Tibia2">
            <origin rpy="1.472774 2.285659 2.018090" xyz="-0.033774 -0.024458 -0.003982" />
            <geometry>
                <mesh filename="file://C:/Users/hp/Desktop/poly2/poly2_Tibia2_coll_20.dae" />
            </geometry>
        </collision>
        <collision name="Tibia2">
            <origin rpy="1.472774 2.285659 2.018090" xyz="-0.033774 -0.024458 -0.003982" />
            <geometry>
                <mesh filename="file://C:/Users/hp/Desktop/poly2/poly2_Tibia2_coll_21.dae" />
            </geometry>
        </collision>
        <collision name="Tibia2">
            <origin rpy="1.472774 2.285659 2.018090" xyz="-0.033774 -0.024458 -0.003982" />
            <geometry>
                <mesh filename="file://C:/Users/hp/Desktop/poly2/poly2_Tibia2_coll_22.dae" />
            </geometry>
        </collision>
        <collision name="Tibia2">
            <origin rpy="1.472774 2.285659 2.018090" xyz="-0.033774 -0.024458 -0.003982" />
            <geometry>
                <mesh filename="file://C:/Users/hp/Desktop/poly2/poly2_Tibia2_coll_23.dae" />
            </geometry>
        </collision>
        <collision name="Tibia2">
            <origin rpy="1.472774 2.285659 2.018090" xyz="-0.033774 -0.024458 -0.003982" />
            <geometry>
                <mesh filename="file://C:/Users/hp/Desktop/poly2/poly2_Tibia2_coll_24.dae" />
            </geometry>
        </collision>
        <collision name="Tibia2">
            <origin rpy="1.472774 2.285659 2.018090" xyz="-0.033774 -0.024458 -0.003982" />
            <geometry>
                <mesh filename="file://C:/Users/hp/Desktop/poly2/poly2_Tibia2_coll_25.dae" />
            </geometry>
        </collision>
        <collision name="Tibia2">
            <origin rpy="1.472774 2.285659 2.018090" xyz="-0.033774 -0.024458 -0.003982" />
            <geometry>
                <mesh filename="file://C:/Users/hp/Desktop/poly2/poly2_Tibia2_coll_26.dae" />
            </geometry>
        </collision>
        <collision name="Tibia2">
            <origin rpy="1.472774 2.285659 2.018090" xyz="-0.033774 -0.024458 -0.003982" />
            <geometry>
                <mesh filename="file://C:/Users/hp/Desktop/poly2/poly2_Tibia2_coll_27.dae" />
            </geometry>
        </collision>
        <visual name="TibiaB">
            <origin rpy="1.472774 2.285659 2.018090" xyz="-0.033774 -0.024458 -0.003982" />
            <geometry>
                <mesh filename="file://C:/Users/hp/Desktop/poly2/poly2_TibiaB_vis_1.dae" />
            </geometry>
            <material name="TibiaB_material">
                <color rgba="0.000000 0.000000 0.000000 1.0" />
            </material>
        </visual>
    </link>
</robot>
